2021-01-14 11:09:18,717 ERROR: Exception on /pedidos [GET] [in c:\users\erezzonico\proyectos\python\borisappback\venv\lib\site-packages\flask\app.py:1892]
Traceback (most recent call last):
  File "c:\users\erezzonico\proyectos\python\borisappback\venv\lib\site-packages\flask\app.py", line 2447, in wsgi_app
    response = self.full_dispatch_request()
  File "c:\users\erezzonico\proyectos\python\borisappback\venv\lib\site-packages\flask\app.py", line 1952, in full_dispatch_request
    rv = self.handle_user_exception(e)
  File "c:\users\erezzonico\proyectos\python\borisappback\venv\lib\site-packages\flask\app.py", line 1821, in handle_user_exception
    reraise(exc_type, exc_value, tb)
  File "c:\users\erezzonico\proyectos\python\borisappback\venv\lib\site-packages\flask\_compat.py", line 39, in reraise
    raise value
  File "c:\users\erezzonico\proyectos\python\borisappback\venv\lib\site-packages\flask\app.py", line 1950, in full_dispatch_request
    rv = self.dispatch_request()
  File "c:\users\erezzonico\proyectos\python\borisappback\venv\lib\site-packages\flask\app.py", line 1936, in dispatch_request
    return self.view_functions[rule.endpoint](**req.view_args)
  File "c:\users\erezzonico\proyectos\python\borisappback\venv\lib\site-packages\flask_login\utils.py", line 272, in decorated_view
    return func(*args, **kwargs)
  File "C:\Users\erezzonico\Proyectos\Python\BorisAppBack\app\main\routes.py", line 51, in ver_pedidos
    pedidos = cargar_pedidos()
  File "C:\Users\erezzonico\Proyectos\Python\BorisAppBack\app\main\interfaces.py", line 18, in cargar_pedidos
    crear_pedido(dict)
  File "C:\Users\erezzonico\Proyectos\Python\BorisAppBack\app\main\interfaces.py", line 51, in crear_pedido
    pertenece = unaEmpresa
  File "<string>", line 4, in __init__
  File "c:\users\erezzonico\proyectos\python\borisappback\venv\lib\site-packages\sqlalchemy\orm\state.py", line 433, in _initialize_instance
    manager.dispatch.init_failure(self, args, kwargs)
  File "c:\users\erezzonico\proyectos\python\borisappback\venv\lib\site-packages\sqlalchemy\util\langhelpers.py", line 70, in __exit__
    with_traceback=exc_tb,
  File "c:\users\erezzonico\proyectos\python\borisappback\venv\lib\site-packages\sqlalchemy\util\compat.py", line 182, in raise_
    raise exception
  File "c:\users\erezzonico\proyectos\python\borisappback\venv\lib\site-packages\sqlalchemy\orm\state.py", line 430, in _initialize_instance
    return manager.original_init(*mixed[1:], **kwargs)
  File "c:\users\erezzonico\proyectos\python\borisappback\venv\lib\site-packages\sqlalchemy\ext\declarative\base.py", line 840, in _declarative_constructor
    "%r is an invalid keyword argument for %s" % (k, cls_.__name__)
TypeError: 'metodo_de_pago' is an invalid keyword argument for Order
2021-01-14 11:10:46,706 INFO: Boris startup [in C:\Users\erezzonico\Proyectos\Python\BorisAppBack\app\__init__.py:71]
2021-01-14 11:10:51,848 ERROR: Exception on /pedidos [GET] [in c:\users\erezzonico\proyectos\python\borisappback\venv\lib\site-packages\flask\app.py:1892]
Traceback (most recent call last):
  File "c:\users\erezzonico\proyectos\python\borisappback\venv\lib\site-packages\flask\app.py", line 2447, in wsgi_app
    response = self.full_dispatch_request()
  File "c:\users\erezzonico\proyectos\python\borisappback\venv\lib\site-packages\flask\app.py", line 1952, in full_dispatch_request
    rv = self.handle_user_exception(e)
  File "c:\users\erezzonico\proyectos\python\borisappback\venv\lib\site-packages\flask\app.py", line 1821, in handle_user_exception
    reraise(exc_type, exc_value, tb)
  File "c:\users\erezzonico\proyectos\python\borisappback\venv\lib\site-packages\flask\_compat.py", line 39, in reraise
    raise value
  File "c:\users\erezzonico\proyectos\python\borisappback\venv\lib\site-packages\flask\app.py", line 1950, in full_dispatch_request
    rv = self.dispatch_request()
  File "c:\users\erezzonico\proyectos\python\borisappback\venv\lib\site-packages\flask\app.py", line 1936, in dispatch_request
    return self.view_functions[rule.endpoint](**req.view_args)
  File "c:\users\erezzonico\proyectos\python\borisappback\venv\lib\site-packages\flask_login\utils.py", line 272, in decorated_view
    return func(*args, **kwargs)
  File "C:\Users\erezzonico\Proyectos\Python\BorisAppBack\app\main\routes.py", line 51, in ver_pedidos
    pedidos = cargar_pedidos()
  File "C:\Users\erezzonico\Proyectos\Python\BorisAppBack\app\main\interfaces.py", line 18, in cargar_pedidos
    crear_pedido(dict)
  File "C:\Users\erezzonico\Proyectos\Python\BorisAppBack\app\main\interfaces.py", line 51, in crear_pedido
    pertenece = unaEmpresa
  File "<string>", line 4, in __init__
  File "c:\users\erezzonico\proyectos\python\borisappback\venv\lib\site-packages\sqlalchemy\orm\state.py", line 433, in _initialize_instance
    manager.dispatch.init_failure(self, args, kwargs)
  File "c:\users\erezzonico\proyectos\python\borisappback\venv\lib\site-packages\sqlalchemy\util\langhelpers.py", line 70, in __exit__
    with_traceback=exc_tb,
  File "c:\users\erezzonico\proyectos\python\borisappback\venv\lib\site-packages\sqlalchemy\util\compat.py", line 182, in raise_
    raise exception
  File "c:\users\erezzonico\proyectos\python\borisappback\venv\lib\site-packages\sqlalchemy\orm\state.py", line 430, in _initialize_instance
    return manager.original_init(*mixed[1:], **kwargs)
  File "c:\users\erezzonico\proyectos\python\borisappback\venv\lib\site-packages\sqlalchemy\ext\declarative\base.py", line 840, in _declarative_constructor
    "%r is an invalid keyword argument for %s" % (k, cls_.__name__)
TypeError: 'sub_staus' is an invalid keyword argument for Order
2021-01-14 11:11:22,313 INFO: Boris startup [in C:\Users\erezzonico\Proyectos\Python\BorisAppBack\app\__init__.py:71]
2021-01-14 11:11:25,483 ERROR: Exception on /pedidos [GET] [in c:\users\erezzonico\proyectos\python\borisappback\venv\lib\site-packages\flask\app.py:1892]
Traceback (most recent call last):
  File "c:\users\erezzonico\proyectos\python\borisappback\venv\lib\site-packages\flask\app.py", line 2447, in wsgi_app
    response = self.full_dispatch_request()
  File "c:\users\erezzonico\proyectos\python\borisappback\venv\lib\site-packages\flask\app.py", line 1952, in full_dispatch_request
    rv = self.handle_user_exception(e)
  File "c:\users\erezzonico\proyectos\python\borisappback\venv\lib\site-packages\flask\app.py", line 1821, in handle_user_exception
    reraise(exc_type, exc_value, tb)
  File "c:\users\erezzonico\proyectos\python\borisappback\venv\lib\site-packages\flask\_compat.py", line 39, in reraise
    raise value
  File "c:\users\erezzonico\proyectos\python\borisappback\venv\lib\site-packages\flask\app.py", line 1950, in full_dispatch_request
    rv = self.dispatch_request()
  File "c:\users\erezzonico\proyectos\python\borisappback\venv\lib\site-packages\flask\app.py", line 1936, in dispatch_request
    return self.view_functions[rule.endpoint](**req.view_args)
  File "c:\users\erezzonico\proyectos\python\borisappback\venv\lib\site-packages\flask_login\utils.py", line 272, in decorated_view
    return func(*args, **kwargs)
  File "C:\Users\erezzonico\Proyectos\Python\BorisAppBack\app\main\routes.py", line 51, in ver_pedidos
    pedidos = cargar_pedidos()
  File "C:\Users\erezzonico\Proyectos\Python\BorisAppBack\app\main\interfaces.py", line 18, in cargar_pedidos
    crear_pedido(dict)
  File "C:\Users\erezzonico\Proyectos\Python\BorisAppBack\app\main\interfaces.py", line 56, in crear_pedido
    unProducto = Producto(
NameError: name 'Producto' is not defined
2021-01-14 11:11:45,390 INFO: Boris startup [in C:\Users\erezzonico\Proyectos\Python\BorisAppBack\app\__init__.py:71]
2021-01-14 11:11:49,506 ERROR: Exception on /pedidos [GET] [in c:\users\erezzonico\proyectos\python\borisappback\venv\lib\site-packages\flask\app.py:1892]
Traceback (most recent call last):
  File "c:\users\erezzonico\proyectos\python\borisappback\venv\lib\site-packages\flask\app.py", line 2447, in wsgi_app
    response = self.full_dispatch_request()
  File "c:\users\erezzonico\proyectos\python\borisappback\venv\lib\site-packages\flask\app.py", line 1952, in full_dispatch_request
    rv = self.handle_user_exception(e)
  File "c:\users\erezzonico\proyectos\python\borisappback\venv\lib\site-packages\flask\app.py", line 1821, in handle_user_exception
    reraise(exc_type, exc_value, tb)
  File "c:\users\erezzonico\proyectos\python\borisappback\venv\lib\site-packages\flask\_compat.py", line 39, in reraise
    raise value
  File "c:\users\erezzonico\proyectos\python\borisappback\venv\lib\site-packages\flask\app.py", line 1950, in full_dispatch_request
    rv = self.dispatch_request()
  File "c:\users\erezzonico\proyectos\python\borisappback\venv\lib\site-packages\flask\app.py", line 1936, in dispatch_request
    return self.view_functions[rule.endpoint](**req.view_args)
  File "c:\users\erezzonico\proyectos\python\borisappback\venv\lib\site-packages\flask_login\utils.py", line 272, in decorated_view
    return func(*args, **kwargs)
  File "C:\Users\erezzonico\Proyectos\Python\BorisAppBack\app\main\routes.py", line 51, in ver_pedidos
    pedidos = cargar_pedidos()
  File "C:\Users\erezzonico\Proyectos\Python\BorisAppBack\app\main\interfaces.py", line 18, in cargar_pedidos
    crear_pedido(dict)
  File "C:\Users\erezzonico\Proyectos\Python\BorisAppBack\app\main\interfaces.py", line 45, in crear_pedido
    payment_method = pedido['orden_medio_de_pago'],
KeyError: 'orden_medio_de_pago'
2021-01-14 11:13:02,230 INFO: Boris startup [in C:\Users\erezzonico\Proyectos\Python\BorisAppBack\app\__init__.py:71]
