2021-01-13 18:12:58,572 ERROR: Exception on /index.html [GET] [in c:\users\erezzonico\proyectos\python\borisappback\venv\lib\site-packages\flask\app.py:1892]
Traceback (most recent call last):
  File "c:\users\erezzonico\proyectos\python\borisappback\venv\lib\site-packages\sqlalchemy\engine\base.py", line 1277, in _execute_context
    cursor, statement, parameters, context
  File "c:\users\erezzonico\proyectos\python\borisappback\venv\lib\site-packages\sqlalchemy\engine\default.py", line 609, in do_execute
    cursor.execute(statement, parameters)
sqlite3.OperationalError: no such table: user

The above exception was the direct cause of the following exception:

Traceback (most recent call last):
  File "c:\users\erezzonico\proyectos\python\borisappback\venv\lib\site-packages\flask\app.py", line 2447, in wsgi_app
    response = self.full_dispatch_request()
  File "c:\users\erezzonico\proyectos\python\borisappback\venv\lib\site-packages\flask\app.py", line 1952, in full_dispatch_request
    rv = self.handle_user_exception(e)
  File "c:\users\erezzonico\proyectos\python\borisappback\venv\lib\site-packages\flask\app.py", line 1821, in handle_user_exception
    reraise(exc_type, exc_value, tb)
  File "c:\users\erezzonico\proyectos\python\borisappback\venv\lib\site-packages\flask\_compat.py", line 39, in reraise
    raise value
  File "c:\users\erezzonico\proyectos\python\borisappback\venv\lib\site-packages\flask\app.py", line 1948, in full_dispatch_request
    rv = self.preprocess_request()
  File "c:\users\erezzonico\proyectos\python\borisappback\venv\lib\site-packages\flask\app.py", line 2242, in preprocess_request
    rv = func()
  File "C:\Users\erezzonico\Proyectos\Python\BorisAppBack\app\main\routes.py", line 14, in before_request
    if current_user.is_authenticated:
  File "c:\users\erezzonico\proyectos\python\borisappback\venv\lib\site-packages\werkzeug\local.py", line 347, in __getattr__
    return getattr(self._get_current_object(), name)
  File "c:\users\erezzonico\proyectos\python\borisappback\venv\lib\site-packages\werkzeug\local.py", line 306, in _get_current_object
    return self.__local()
  File "c:\users\erezzonico\proyectos\python\borisappback\venv\lib\site-packages\flask_login\utils.py", line 26, in <lambda>
    current_user = LocalProxy(lambda: _get_user())
  File "c:\users\erezzonico\proyectos\python\borisappback\venv\lib\site-packages\flask_login\utils.py", line 346, in _get_user
    current_app.login_manager._load_user()
  File "c:\users\erezzonico\proyectos\python\borisappback\venv\lib\site-packages\flask_login\login_manager.py", line 318, in _load_user
    user = self._user_callback(user_id)
  File "C:\Users\erezzonico\Proyectos\Python\BorisAppBack\app\models.py", line 74, in load_user
    return User.query.get(int(id))
  File "c:\users\erezzonico\proyectos\python\borisappback\venv\lib\site-packages\sqlalchemy\orm\query.py", line 1018, in get
    return self._get_impl(ident, loading.load_on_pk_identity)
  File "c:\users\erezzonico\proyectos\python\borisappback\venv\lib\site-packages\sqlalchemy\orm\query.py", line 1135, in _get_impl
    return db_load_fn(self, primary_key_identity)
  File "c:\users\erezzonico\proyectos\python\borisappback\venv\lib\site-packages\sqlalchemy\orm\loading.py", line 286, in load_on_pk_identity
    return q.one()
  File "c:\users\erezzonico\proyectos\python\borisappback\venv\lib\site-packages\sqlalchemy\orm\query.py", line 3490, in one
    ret = self.one_or_none()
  File "c:\users\erezzonico\proyectos\python\borisappback\venv\lib\site-packages\sqlalchemy\orm\query.py", line 3459, in one_or_none
    ret = list(self)
  File "c:\users\erezzonico\proyectos\python\borisappback\venv\lib\site-packages\sqlalchemy\orm\query.py", line 3535, in __iter__
    return self._execute_and_instances(context)
  File "c:\users\erezzonico\proyectos\python\borisappback\venv\lib\site-packages\sqlalchemy\orm\query.py", line 3560, in _execute_and_instances
    result = conn.execute(querycontext.statement, self._params)
  File "c:\users\erezzonico\proyectos\python\borisappback\venv\lib\site-packages\sqlalchemy\engine\base.py", line 1011, in execute
    return meth(self, multiparams, params)
  File "c:\users\erezzonico\proyectos\python\borisappback\venv\lib\site-packages\sqlalchemy\sql\elements.py", line 298, in _execute_on_connection
    return connection._execute_clauseelement(self, multiparams, params)
  File "c:\users\erezzonico\proyectos\python\borisappback\venv\lib\site-packages\sqlalchemy\engine\base.py", line 1130, in _execute_clauseelement
    distilled_params,
  File "c:\users\erezzonico\proyectos\python\borisappback\venv\lib\site-packages\sqlalchemy\engine\base.py", line 1317, in _execute_context
    e, statement, parameters, cursor, context
  File "c:\users\erezzonico\proyectos\python\borisappback\venv\lib\site-packages\sqlalchemy\engine\base.py", line 1511, in _handle_dbapi_exception
    sqlalchemy_exception, with_traceback=exc_info[2], from_=e
  File "c:\users\erezzonico\proyectos\python\borisappback\venv\lib\site-packages\sqlalchemy\util\compat.py", line 182, in raise_
    raise exception
  File "c:\users\erezzonico\proyectos\python\borisappback\venv\lib\site-packages\sqlalchemy\engine\base.py", line 1277, in _execute_context
    cursor, statement, parameters, context
  File "c:\users\erezzonico\proyectos\python\borisappback\venv\lib\site-packages\sqlalchemy\engine\default.py", line 609, in do_execute
    cursor.execute(statement, parameters)
sqlalchemy.exc.OperationalError: (sqlite3.OperationalError) no such table: user
[SQL: SELECT user.id AS user_id, user.username AS user_username, user.email AS user_email, user.password_hash AS user_password_hash, user.last_seen AS user_last_seen, user.company_id AS user_company_id 
FROM user 
WHERE user.id = ?]
[parameters: (1,)]
(Background on this error at: http://sqlalche.me/e/13/e3q8)
2021-01-13 18:15:05,715 INFO: Boris startup [in C:\Users\erezzonico\Proyectos\Python\BorisAppBack\app\__init__.py:71]
2021-01-13 18:15:12,380 INFO: Boris startup [in C:\Users\erezzonico\Proyectos\Python\BorisAppBack\app\__init__.py:71]
2021-01-13 18:15:20,307 INFO: Boris startup [in C:\Users\erezzonico\Proyectos\Python\BorisAppBack\app\__init__.py:71]
2021-01-13 18:15:29,611 INFO: Boris startup [in C:\Users\erezzonico\Proyectos\Python\BorisAppBack\app\__init__.py:71]
2021-01-14 10:57:16,016 INFO: Boris startup [in C:\Users\erezzonico\Proyectos\Python\BorisAppBack\app\__init__.py:71]
