2021-01-15 19:29:45,775 ERROR: Exception on /ordenes/Shipping [GET] [in c:\users\erezzonico\proyectos\python\borisappback\venv\lib\site-packages\flask\app.py:1892]
Traceback (most recent call last):
  File "c:\users\erezzonico\proyectos\python\borisappback\venv\lib\site-packages\flask\app.py", line 2447, in wsgi_app
    response = self.full_dispatch_request()
  File "c:\users\erezzonico\proyectos\python\borisappback\venv\lib\site-packages\flask\app.py", line 1952, in full_dispatch_request
    rv = self.handle_user_exception(e)
  File "c:\users\erezzonico\proyectos\python\borisappback\venv\lib\site-packages\flask\app.py", line 1821, in handle_user_exception
    reraise(exc_type, exc_value, tb)
  File "c:\users\erezzonico\proyectos\python\borisappback\venv\lib\site-packages\flask\_compat.py", line 39, in reraise
    raise value
  File "c:\users\erezzonico\proyectos\python\borisappback\venv\lib\site-packages\flask\app.py", line 1950, in full_dispatch_request
    rv = self.dispatch_request()
  File "c:\users\erezzonico\proyectos\python\borisappback\venv\lib\site-packages\flask\app.py", line 1936, in dispatch_request
    return self.view_functions[rule.endpoint](**req.view_args)
  File "c:\users\erezzonico\proyectos\python\borisappback\venv\lib\site-packages\flask_login\utils.py", line 272, in decorated_view
    return func(*args, **kwargs)
  File "C:\Users\erezzonico\Proyectos\Python\BorisAppBack\app\main\routes.py", line 65, in ver_ordenes
    ordenes = query(Order_header).filter_by(store = current_user.store, status = estado)
NameError: name 'query' is not defined
2021-01-15 19:30:01,294 INFO: Boris startup [in C:\Users\erezzonico\Proyectos\Python\BorisAppBack\app\__init__.py:71]
2021-01-15 19:30:04,498 ERROR: Exception on /ordenes/Shipping [GET] [in c:\users\erezzonico\proyectos\python\borisappback\venv\lib\site-packages\flask\app.py:1892]
Traceback (most recent call last):
  File "c:\users\erezzonico\proyectos\python\borisappback\venv\lib\site-packages\flask\app.py", line 2447, in wsgi_app
    response = self.full_dispatch_request()
  File "c:\users\erezzonico\proyectos\python\borisappback\venv\lib\site-packages\flask\app.py", line 1952, in full_dispatch_request
    rv = self.handle_user_exception(e)
  File "c:\users\erezzonico\proyectos\python\borisappback\venv\lib\site-packages\flask\app.py", line 1821, in handle_user_exception
    reraise(exc_type, exc_value, tb)
  File "c:\users\erezzonico\proyectos\python\borisappback\venv\lib\site-packages\flask\_compat.py", line 39, in reraise
    raise value
  File "c:\users\erezzonico\proyectos\python\borisappback\venv\lib\site-packages\flask\app.py", line 1950, in full_dispatch_request
    rv = self.dispatch_request()
  File "c:\users\erezzonico\proyectos\python\borisappback\venv\lib\site-packages\flask\app.py", line 1936, in dispatch_request
    return self.view_functions[rule.endpoint](**req.view_args)
  File "c:\users\erezzonico\proyectos\python\borisappback\venv\lib\site-packages\flask_login\utils.py", line 272, in decorated_view
    return func(*args, **kwargs)
  File "C:\Users\erezzonico\Proyectos\Python\BorisAppBack\app\main\routes.py", line 65, in ver_ordenes
    ordenes = Query(Order_header).filter_by(store = current_user.store, status = estado)
NameError: name 'Query' is not defined
2021-01-15 19:31:35,636 INFO: Boris startup [in C:\Users\erezzonico\Proyectos\Python\BorisAppBack\app\__init__.py:71]
2021-01-15 19:31:40,655 ERROR: Exception on /ordenes/Shipping [GET] [in c:\users\erezzonico\proyectos\python\borisappback\venv\lib\site-packages\flask\app.py:1892]
Traceback (most recent call last):
  File "c:\users\erezzonico\proyectos\python\borisappback\venv\lib\site-packages\flask\app.py", line 2447, in wsgi_app
    response = self.full_dispatch_request()
  File "c:\users\erezzonico\proyectos\python\borisappback\venv\lib\site-packages\flask\app.py", line 1952, in full_dispatch_request
    rv = self.handle_user_exception(e)
  File "c:\users\erezzonico\proyectos\python\borisappback\venv\lib\site-packages\flask\app.py", line 1821, in handle_user_exception
    reraise(exc_type, exc_value, tb)
  File "c:\users\erezzonico\proyectos\python\borisappback\venv\lib\site-packages\flask\_compat.py", line 39, in reraise
    raise value
  File "c:\users\erezzonico\proyectos\python\borisappback\venv\lib\site-packages\flask\app.py", line 1950, in full_dispatch_request
    rv = self.dispatch_request()
  File "c:\users\erezzonico\proyectos\python\borisappback\venv\lib\site-packages\flask\app.py", line 1936, in dispatch_request
    return self.view_functions[rule.endpoint](**req.view_args)
  File "c:\users\erezzonico\proyectos\python\borisappback\venv\lib\site-packages\flask_login\utils.py", line 272, in decorated_view
    return func(*args, **kwargs)
  File "C:\Users\erezzonico\Proyectos\Python\BorisAppBack\app\main\routes.py", line 65, in ver_ordenes
    ordenes = db.session.query(Order_header).filter(store = current_user.store, status = estado)
TypeError: filter() got an unexpected keyword argument 'store'
2021-01-15 19:32:38,054 INFO: Boris startup [in C:\Users\erezzonico\Proyectos\Python\BorisAppBack\app\__init__.py:71]
2021-01-15 19:32:42,767 ERROR: Exception on /ordenes/Shipping [GET] [in c:\users\erezzonico\proyectos\python\borisappback\venv\lib\site-packages\flask\app.py:1892]
Traceback (most recent call last):
  File "c:\users\erezzonico\proyectos\python\borisappback\venv\lib\site-packages\flask\app.py", line 2447, in wsgi_app
    response = self.full_dispatch_request()
  File "c:\users\erezzonico\proyectos\python\borisappback\venv\lib\site-packages\flask\app.py", line 1952, in full_dispatch_request
    rv = self.handle_user_exception(e)
  File "c:\users\erezzonico\proyectos\python\borisappback\venv\lib\site-packages\flask\app.py", line 1821, in handle_user_exception
    reraise(exc_type, exc_value, tb)
  File "c:\users\erezzonico\proyectos\python\borisappback\venv\lib\site-packages\flask\_compat.py", line 39, in reraise
    raise value
  File "c:\users\erezzonico\proyectos\python\borisappback\venv\lib\site-packages\flask\app.py", line 1950, in full_dispatch_request
    rv = self.dispatch_request()
  File "c:\users\erezzonico\proyectos\python\borisappback\venv\lib\site-packages\flask\app.py", line 1936, in dispatch_request
    return self.view_functions[rule.endpoint](**req.view_args)
  File "c:\users\erezzonico\proyectos\python\borisappback\venv\lib\site-packages\flask_login\utils.py", line 272, in decorated_view
    return func(*args, **kwargs)
  File "C:\Users\erezzonico\Proyectos\Python\BorisAppBack\app\main\routes.py", line 65, in ver_ordenes
    ordenes = db.session.query(Order_header).filter(and_(store = current_user.store, status = estado))
NameError: name 'and_' is not defined
2021-01-15 19:38:34,621 INFO: Boris startup [in C:\Users\erezzonico\Proyectos\Python\BorisAppBack\app\__init__.py:71]
2021-01-15 19:38:39,778 ERROR: Exception on /ordenes/Shipping [GET] [in c:\users\erezzonico\proyectos\python\borisappback\venv\lib\site-packages\flask\app.py:1892]
Traceback (most recent call last):
  File "c:\users\erezzonico\proyectos\python\borisappback\venv\lib\site-packages\flask\app.py", line 2447, in wsgi_app
    response = self.full_dispatch_request()
  File "c:\users\erezzonico\proyectos\python\borisappback\venv\lib\site-packages\flask\app.py", line 1952, in full_dispatch_request
    rv = self.handle_user_exception(e)
  File "c:\users\erezzonico\proyectos\python\borisappback\venv\lib\site-packages\flask\app.py", line 1821, in handle_user_exception
    reraise(exc_type, exc_value, tb)
  File "c:\users\erezzonico\proyectos\python\borisappback\venv\lib\site-packages\flask\_compat.py", line 39, in reraise
    raise value
  File "c:\users\erezzonico\proyectos\python\borisappback\venv\lib\site-packages\flask\app.py", line 1950, in full_dispatch_request
    rv = self.dispatch_request()
  File "c:\users\erezzonico\proyectos\python\borisappback\venv\lib\site-packages\flask\app.py", line 1936, in dispatch_request
    return self.view_functions[rule.endpoint](**req.view_args)
  File "c:\users\erezzonico\proyectos\python\borisappback\venv\lib\site-packages\flask_login\utils.py", line 272, in decorated_view
    return func(*args, **kwargs)
  File "C:\Users\erezzonico\Proyectos\Python\BorisAppBack\app\main\routes.py", line 65, in ver_ordenes
    ordenes = db.session.query(Order_header).filter(store = current_user.store).filter(status = estado)
TypeError: filter() got an unexpected keyword argument 'store'
2021-01-15 19:39:35,322 INFO: Boris startup [in C:\Users\erezzonico\Proyectos\Python\BorisAppBack\app\__init__.py:71]
