2021-01-17 12:04:54,311 ERROR: Exception on /webhook [POST] [in c:\users\erezzonico\proyectos\python\borisappback\venv\lib\site-packages\flask\app.py:1892]
Traceback (most recent call last):
  File "c:\users\erezzonico\proyectos\python\borisappback\venv\lib\site-packages\sqlalchemy\engine\base.py", line 1277, in _execute_context
    cursor, statement, parameters, context
  File "c:\users\erezzonico\proyectos\python\borisappback\venv\lib\site-packages\sqlalchemy\engine\default.py", line 609, in do_execute
    cursor.execute(statement, parameters)
sqlite3.InterfaceError: Error binding parameter 2 - probably unsupported type.

The above exception was the direct cause of the following exception:

Traceback (most recent call last):
  File "c:\users\erezzonico\proyectos\python\borisappback\venv\lib\site-packages\flask\app.py", line 2447, in wsgi_app
    response = self.full_dispatch_request()
  File "c:\users\erezzonico\proyectos\python\borisappback\venv\lib\site-packages\flask\app.py", line 1952, in full_dispatch_request
    rv = self.handle_user_exception(e)
  File "c:\users\erezzonico\proyectos\python\borisappback\venv\lib\site-packages\flask\app.py", line 1821, in handle_user_exception
    reraise(exc_type, exc_value, tb)
  File "c:\users\erezzonico\proyectos\python\borisappback\venv\lib\site-packages\flask\_compat.py", line 39, in reraise
    raise value
  File "c:\users\erezzonico\proyectos\python\borisappback\venv\lib\site-packages\flask\app.py", line 1950, in full_dispatch_request
    rv = self.dispatch_request()
  File "c:\users\erezzonico\proyectos\python\borisappback\venv\lib\site-packages\flask\app.py", line 1936, in dispatch_request
    return self.view_functions[rule.endpoint](**req.view_args)
  File "C:\Users\erezzonico\Proyectos\Python\BorisAppBack\app\main\routes.py", line 170, in webhook
    db.session.commit()
  File "c:\users\erezzonico\proyectos\python\borisappback\venv\lib\site-packages\sqlalchemy\orm\scoping.py", line 163, in do
    return getattr(self.registry(), name)(*args, **kwargs)
  File "c:\users\erezzonico\proyectos\python\borisappback\venv\lib\site-packages\sqlalchemy\orm\session.py", line 1046, in commit
    self.transaction.commit()
  File "c:\users\erezzonico\proyectos\python\borisappback\venv\lib\site-packages\sqlalchemy\orm\session.py", line 504, in commit
    self._prepare_impl()
  File "c:\users\erezzonico\proyectos\python\borisappback\venv\lib\site-packages\sqlalchemy\orm\session.py", line 483, in _prepare_impl
    self.session.flush()
  File "c:\users\erezzonico\proyectos\python\borisappback\venv\lib\site-packages\sqlalchemy\orm\session.py", line 2540, in flush
    self._flush(objects)
  File "c:\users\erezzonico\proyectos\python\borisappback\venv\lib\site-packages\sqlalchemy\orm\session.py", line 2682, in _flush
    transaction.rollback(_capture_exception=True)
  File "c:\users\erezzonico\proyectos\python\borisappback\venv\lib\site-packages\sqlalchemy\util\langhelpers.py", line 70, in __exit__
    with_traceback=exc_tb,
  File "c:\users\erezzonico\proyectos\python\borisappback\venv\lib\site-packages\sqlalchemy\util\compat.py", line 182, in raise_
    raise exception
  File "c:\users\erezzonico\proyectos\python\borisappback\venv\lib\site-packages\sqlalchemy\orm\session.py", line 2642, in _flush
    flush_context.execute()
  File "c:\users\erezzonico\proyectos\python\borisappback\venv\lib\site-packages\sqlalchemy\orm\unitofwork.py", line 422, in execute
    rec.execute(self)
  File "c:\users\erezzonico\proyectos\python\borisappback\venv\lib\site-packages\sqlalchemy\orm\unitofwork.py", line 589, in execute
    uow,
  File "c:\users\erezzonico\proyectos\python\borisappback\venv\lib\site-packages\sqlalchemy\orm\persistence.py", line 245, in save_obj
    insert,
  File "c:\users\erezzonico\proyectos\python\borisappback\venv\lib\site-packages\sqlalchemy\orm\persistence.py", line 1136, in _emit_insert_statements
    statement, params
  File "c:\users\erezzonico\proyectos\python\borisappback\venv\lib\site-packages\sqlalchemy\engine\base.py", line 1011, in execute
    return meth(self, multiparams, params)
  File "c:\users\erezzonico\proyectos\python\borisappback\venv\lib\site-packages\sqlalchemy\sql\elements.py", line 298, in _execute_on_connection
    return connection._execute_clauseelement(self, multiparams, params)
  File "c:\users\erezzonico\proyectos\python\borisappback\venv\lib\site-packages\sqlalchemy\engine\base.py", line 1130, in _execute_clauseelement
    distilled_params,
  File "c:\users\erezzonico\proyectos\python\borisappback\venv\lib\site-packages\sqlalchemy\engine\base.py", line 1317, in _execute_context
    e, statement, parameters, cursor, context
  File "c:\users\erezzonico\proyectos\python\borisappback\venv\lib\site-packages\sqlalchemy\engine\base.py", line 1511, in _handle_dbapi_exception
    sqlalchemy_exception, with_traceback=exc_info[2], from_=e
  File "c:\users\erezzonico\proyectos\python\borisappback\venv\lib\site-packages\sqlalchemy\util\compat.py", line 182, in raise_
    raise exception
  File "c:\users\erezzonico\proyectos\python\borisappback\venv\lib\site-packages\sqlalchemy\engine\base.py", line 1277, in _execute_context
    cursor, statement, parameters, context
  File "c:\users\erezzonico\proyectos\python\borisappback\venv\lib\site-packages\sqlalchemy\engine\default.py", line 609, in do_execute
    cursor.execute(statement, parameters)
sqlalchemy.exc.InterfaceError: <unprintable InterfaceError object>
2021-01-17 12:05:42,242 INFO: Boris startup [in C:\Users\erezzonico\Proyectos\Python\BorisAppBack\app\__init__.py:71]
2021-01-17 16:29:09,023 INFO: Boris startup [in C:\Users\erezzonico\Proyectos\Python\BorisAppBack\app\__init__.py:71]
