2021-01-16 18:35:56,233 ERROR: Exception on /cargar_pedidos [GET] [in c:\users\erezzonico\proyectos\python\borisappback\venv\lib\site-packages\flask\app.py:1892]
Traceback (most recent call last):
  File "c:\users\erezzonico\proyectos\python\borisappback\venv\lib\site-packages\flask\app.py", line 2447, in wsgi_app
    response = self.full_dispatch_request()
  File "c:\users\erezzonico\proyectos\python\borisappback\venv\lib\site-packages\flask\app.py", line 1952, in full_dispatch_request
    rv = self.handle_user_exception(e)
  File "c:\users\erezzonico\proyectos\python\borisappback\venv\lib\site-packages\flask\app.py", line 1821, in handle_user_exception
    reraise(exc_type, exc_value, tb)
  File "c:\users\erezzonico\proyectos\python\borisappback\venv\lib\site-packages\flask\_compat.py", line 39, in reraise
    raise value
  File "c:\users\erezzonico\proyectos\python\borisappback\venv\lib\site-packages\flask\app.py", line 1950, in full_dispatch_request
    rv = self.dispatch_request()
  File "c:\users\erezzonico\proyectos\python\borisappback\venv\lib\site-packages\flask\app.py", line 1936, in dispatch_request
    return self.view_functions[rule.endpoint](**req.view_args)
  File "c:\users\erezzonico\proyectos\python\borisappback\venv\lib\site-packages\flask_login\utils.py", line 272, in decorated_view
    return func(*args, **kwargs)
  File "C:\Users\erezzonico\Proyectos\Python\BorisAppBack\app\main\routes.py", line 100, in upload_pedidos
    cargar_pedidos()
  File "C:\Users\erezzonico\Proyectos\Python\BorisAppBack\app\main\interfaces.py", line 18, in cargar_pedidos
    crear_pedido(dict)
  File "C:\Users\erezzonico\Proyectos\Python\BorisAppBack\app\main\interfaces.py", line 57, in crear_pedido
    pertenece = unaEmpresa
  File "<string>", line 4, in __init__
  File "c:\users\erezzonico\proyectos\python\borisappback\venv\lib\site-packages\sqlalchemy\orm\state.py", line 433, in _initialize_instance
    manager.dispatch.init_failure(self, args, kwargs)
  File "c:\users\erezzonico\proyectos\python\borisappback\venv\lib\site-packages\sqlalchemy\util\langhelpers.py", line 70, in __exit__
    with_traceback=exc_tb,
  File "c:\users\erezzonico\proyectos\python\borisappback\venv\lib\site-packages\sqlalchemy\util\compat.py", line 182, in raise_
    raise exception
  File "c:\users\erezzonico\proyectos\python\borisappback\venv\lib\site-packages\sqlalchemy\orm\state.py", line 430, in _initialize_instance
    return manager.original_init(*mixed[1:], **kwargs)
  File "c:\users\erezzonico\proyectos\python\borisappback\venv\lib\site-packages\sqlalchemy\ext\declarative\base.py", line 840, in _declarative_constructor
    "%r is an invalid keyword argument for %s" % (k, cls_.__name__)
TypeError: 'last_update_date' is an invalid keyword argument for Order_header
2021-01-16 18:37:48,560 INFO: Boris startup [in C:\Users\erezzonico\Proyectos\Python\BorisAppBack\app\__init__.py:71]
2021-01-16 18:37:51,895 ERROR: Exception on /cargar_pedidos [GET] [in c:\users\erezzonico\proyectos\python\borisappback\venv\lib\site-packages\flask\app.py:1892]
Traceback (most recent call last):
  File "c:\users\erezzonico\proyectos\python\borisappback\venv\lib\site-packages\sqlalchemy\engine\base.py", line 1204, in _execute_context
    context = constructor(dialect, self, conn, *args)
  File "c:\users\erezzonico\proyectos\python\borisappback\venv\lib\site-packages\sqlalchemy\engine\default.py", line 855, in _init_compiled
    param.append(processors[key](compiled_params[key]))
  File "c:\users\erezzonico\proyectos\python\borisappback\venv\lib\site-packages\sqlalchemy\dialects\sqlite\base.py", line 791, in process
    "SQLite DateTime type only accepts Python "
TypeError: SQLite DateTime type only accepts Python datetime and date objects as input.

The above exception was the direct cause of the following exception:

Traceback (most recent call last):
  File "c:\users\erezzonico\proyectos\python\borisappback\venv\lib\site-packages\flask\app.py", line 2447, in wsgi_app
    response = self.full_dispatch_request()
  File "c:\users\erezzonico\proyectos\python\borisappback\venv\lib\site-packages\flask\app.py", line 1952, in full_dispatch_request
    rv = self.handle_user_exception(e)
  File "c:\users\erezzonico\proyectos\python\borisappback\venv\lib\site-packages\flask\app.py", line 1821, in handle_user_exception
    reraise(exc_type, exc_value, tb)
  File "c:\users\erezzonico\proyectos\python\borisappback\venv\lib\site-packages\flask\_compat.py", line 39, in reraise
    raise value
  File "c:\users\erezzonico\proyectos\python\borisappback\venv\lib\site-packages\flask\app.py", line 1950, in full_dispatch_request
    rv = self.dispatch_request()
  File "c:\users\erezzonico\proyectos\python\borisappback\venv\lib\site-packages\flask\app.py", line 1936, in dispatch_request
    return self.view_functions[rule.endpoint](**req.view_args)
  File "c:\users\erezzonico\proyectos\python\borisappback\venv\lib\site-packages\flask_login\utils.py", line 272, in decorated_view
    return func(*args, **kwargs)
  File "C:\Users\erezzonico\Proyectos\Python\BorisAppBack\app\main\routes.py", line 100, in upload_pedidos
    cargar_pedidos()
  File "C:\Users\erezzonico\Proyectos\Python\BorisAppBack\app\main\interfaces.py", line 18, in cargar_pedidos
    crear_pedido(dict)
  File "C:\Users\erezzonico\Proyectos\Python\BorisAppBack\app\main\interfaces.py", line 78, in crear_pedido
    db.session.commit()
  File "c:\users\erezzonico\proyectos\python\borisappback\venv\lib\site-packages\sqlalchemy\orm\scoping.py", line 163, in do
    return getattr(self.registry(), name)(*args, **kwargs)
  File "c:\users\erezzonico\proyectos\python\borisappback\venv\lib\site-packages\sqlalchemy\orm\session.py", line 1046, in commit
    self.transaction.commit()
  File "c:\users\erezzonico\proyectos\python\borisappback\venv\lib\site-packages\sqlalchemy\orm\session.py", line 504, in commit
    self._prepare_impl()
  File "c:\users\erezzonico\proyectos\python\borisappback\venv\lib\site-packages\sqlalchemy\orm\session.py", line 483, in _prepare_impl
    self.session.flush()
  File "c:\users\erezzonico\proyectos\python\borisappback\venv\lib\site-packages\sqlalchemy\orm\session.py", line 2540, in flush
    self._flush(objects)
  File "c:\users\erezzonico\proyectos\python\borisappback\venv\lib\site-packages\sqlalchemy\orm\session.py", line 2682, in _flush
    transaction.rollback(_capture_exception=True)
  File "c:\users\erezzonico\proyectos\python\borisappback\venv\lib\site-packages\sqlalchemy\util\langhelpers.py", line 70, in __exit__
    with_traceback=exc_tb,
  File "c:\users\erezzonico\proyectos\python\borisappback\venv\lib\site-packages\sqlalchemy\util\compat.py", line 182, in raise_
    raise exception
  File "c:\users\erezzonico\proyectos\python\borisappback\venv\lib\site-packages\sqlalchemy\orm\session.py", line 2642, in _flush
    flush_context.execute()
  File "c:\users\erezzonico\proyectos\python\borisappback\venv\lib\site-packages\sqlalchemy\orm\unitofwork.py", line 422, in execute
    rec.execute(self)
  File "c:\users\erezzonico\proyectos\python\borisappback\venv\lib\site-packages\sqlalchemy\orm\unitofwork.py", line 589, in execute
    uow,
  File "c:\users\erezzonico\proyectos\python\borisappback\venv\lib\site-packages\sqlalchemy\orm\persistence.py", line 245, in save_obj
    insert,
  File "c:\users\erezzonico\proyectos\python\borisappback\venv\lib\site-packages\sqlalchemy\orm\persistence.py", line 1136, in _emit_insert_statements
    statement, params
  File "c:\users\erezzonico\proyectos\python\borisappback\venv\lib\site-packages\sqlalchemy\engine\base.py", line 1011, in execute
    return meth(self, multiparams, params)
  File "c:\users\erezzonico\proyectos\python\borisappback\venv\lib\site-packages\sqlalchemy\sql\elements.py", line 298, in _execute_on_connection
    return connection._execute_clauseelement(self, multiparams, params)
  File "c:\users\erezzonico\proyectos\python\borisappback\venv\lib\site-packages\sqlalchemy\engine\base.py", line 1130, in _execute_clauseelement
    distilled_params,
  File "c:\users\erezzonico\proyectos\python\borisappback\venv\lib\site-packages\sqlalchemy\engine\base.py", line 1207, in _execute_context
    e, util.text_type(statement), parameters, None, None
  File "c:\users\erezzonico\proyectos\python\borisappback\venv\lib\site-packages\sqlalchemy\engine\base.py", line 1511, in _handle_dbapi_exception
    sqlalchemy_exception, with_traceback=exc_info[2], from_=e
  File "c:\users\erezzonico\proyectos\python\borisappback\venv\lib\site-packages\sqlalchemy\util\compat.py", line 182, in raise_
    raise exception
  File "c:\users\erezzonico\proyectos\python\borisappback\venv\lib\site-packages\sqlalchemy\engine\base.py", line 1204, in _execute_context
    context = constructor(dialect, self, conn, *args)
  File "c:\users\erezzonico\proyectos\python\borisappback\venv\lib\site-packages\sqlalchemy\engine\default.py", line 855, in _init_compiled
    param.append(processors[key](compiled_params[key]))
  File "c:\users\erezzonico\proyectos\python\borisappback\venv\lib\site-packages\sqlalchemy\dialects\sqlite\base.py", line 791, in process
    "SQLite DateTime type only accepts Python "
sqlalchemy.exc.StatementError: (builtins.TypeError) SQLite DateTime type only accepts Python datetime and date objects as input.
[SQL: INSERT INTO order_header (order_number, order_id_anterior, creation_date, payment_method, payment_card, courier_order_id, status, sub_status, customer_address, customer_number, customer_floor, customer_zipcode, customer_locality, customer_city, customer_province, customer_country, customer_id, store) VALUES (?, ?, ?, ?, ?, ?, ?, ?, ?, ?, ?, ?, ?, ?, ?, ?, ?, ?)]
[parameters: [{'customer_locality': 'Belgrano', 'payment_method': 'custom', 'order_id_anterior': 337988237, 'courier_order_id': '2e4b55e0-5746-11eb-861a-0545b2e031 ... (247 characters truncated) ... '2021-01-15 15:27:03.539200', 'status': 'Shipping', 'customer_zipcode': '1428', 'customer_number': '1965', 'order_number': 102, 'payment_card': None}]]
