2021-01-15 15:23:26,472 INFO: Boris startup [in C:\Users\erezzonico\Proyectos\Python\BorisAppBack\app\__init__.py:71]
2021-01-15 15:23:31,763 INFO: Boris startup [in C:\Users\erezzonico\Proyectos\Python\BorisAppBack\app\__init__.py:71]
2021-01-15 15:23:46,494 INFO: Boris startup [in C:\Users\erezzonico\Proyectos\Python\BorisAppBack\app\__init__.py:71]
2021-01-15 15:24:05,110 ERROR: Exception on /cargar_pedidos [GET] [in c:\users\erezzonico\proyectos\python\borisappback\venv\lib\site-packages\flask\app.py:1892]
Traceback (most recent call last):
  File "c:\users\erezzonico\proyectos\python\borisappback\venv\lib\site-packages\flask\app.py", line 2447, in wsgi_app
    response = self.full_dispatch_request()
  File "c:\users\erezzonico\proyectos\python\borisappback\venv\lib\site-packages\flask\app.py", line 1952, in full_dispatch_request
    rv = self.handle_user_exception(e)
  File "c:\users\erezzonico\proyectos\python\borisappback\venv\lib\site-packages\flask\app.py", line 1821, in handle_user_exception
    reraise(exc_type, exc_value, tb)
  File "c:\users\erezzonico\proyectos\python\borisappback\venv\lib\site-packages\flask\_compat.py", line 39, in reraise
    raise value
  File "c:\users\erezzonico\proyectos\python\borisappback\venv\lib\site-packages\flask\app.py", line 1950, in full_dispatch_request
    rv = self.dispatch_request()
  File "c:\users\erezzonico\proyectos\python\borisappback\venv\lib\site-packages\flask\app.py", line 1936, in dispatch_request
    return self.view_functions[rule.endpoint](**req.view_args)
  File "c:\users\erezzonico\proyectos\python\borisappback\venv\lib\site-packages\flask_login\utils.py", line 272, in decorated_view
    return func(*args, **kwargs)
  File "C:\Users\erezzonico\Proyectos\Python\BorisAppBack\app\main\routes.py", line 80, in upload_pedidos
    cargar_pedidos()
  File "C:\Users\erezzonico\Proyectos\Python\BorisAppBack\app\main\interfaces.py", line 19, in cargar_pedidos
    crear_pedido(dict)
  File "C:\Users\erezzonico\Proyectos\Python\BorisAppBack\app\main\interfaces.py", line 73, in crear_pedido
    productos = unaOrden
  File "<string>", line 4, in __init__
  File "c:\users\erezzonico\proyectos\python\borisappback\venv\lib\site-packages\sqlalchemy\orm\state.py", line 433, in _initialize_instance
    manager.dispatch.init_failure(self, args, kwargs)
  File "c:\users\erezzonico\proyectos\python\borisappback\venv\lib\site-packages\sqlalchemy\util\langhelpers.py", line 70, in __exit__
    with_traceback=exc_tb,
  File "c:\users\erezzonico\proyectos\python\borisappback\venv\lib\site-packages\sqlalchemy\util\compat.py", line 182, in raise_
    raise exception
  File "c:\users\erezzonico\proyectos\python\borisappback\venv\lib\site-packages\sqlalchemy\orm\state.py", line 430, in _initialize_instance
    return manager.original_init(*mixed[1:], **kwargs)
  File "c:\users\erezzonico\proyectos\python\borisappback\venv\lib\site-packages\sqlalchemy\ext\declarative\base.py", line 840, in _declarative_constructor
    "%r is an invalid keyword argument for %s" % (k, cls_.__name__)
TypeError: 'Order_line_number' is an invalid keyword argument for Order_detail
2021-01-15 15:24:24,590 INFO: Boris startup [in C:\Users\erezzonico\Proyectos\Python\BorisAppBack\app\__init__.py:71]
2021-01-15 15:24:27,542 ERROR: Exception on /cargar_pedidos [GET] [in c:\users\erezzonico\proyectos\python\borisappback\venv\lib\site-packages\flask\app.py:1892]
Traceback (most recent call last):
  File "c:\users\erezzonico\proyectos\python\borisappback\venv\lib\site-packages\flask\app.py", line 2447, in wsgi_app
    response = self.full_dispatch_request()
  File "c:\users\erezzonico\proyectos\python\borisappback\venv\lib\site-packages\flask\app.py", line 1952, in full_dispatch_request
    rv = self.handle_user_exception(e)
  File "c:\users\erezzonico\proyectos\python\borisappback\venv\lib\site-packages\flask\app.py", line 1821, in handle_user_exception
    reraise(exc_type, exc_value, tb)
  File "c:\users\erezzonico\proyectos\python\borisappback\venv\lib\site-packages\flask\_compat.py", line 39, in reraise
    raise value
  File "c:\users\erezzonico\proyectos\python\borisappback\venv\lib\site-packages\flask\app.py", line 1950, in full_dispatch_request
    rv = self.dispatch_request()
  File "c:\users\erezzonico\proyectos\python\borisappback\venv\lib\site-packages\flask\app.py", line 1936, in dispatch_request
    return self.view_functions[rule.endpoint](**req.view_args)
  File "c:\users\erezzonico\proyectos\python\borisappback\venv\lib\site-packages\flask_login\utils.py", line 272, in decorated_view
    return func(*args, **kwargs)
  File "C:\Users\erezzonico\Proyectos\Python\BorisAppBack\app\main\routes.py", line 80, in upload_pedidos
    cargar_pedidos()
  File "C:\Users\erezzonico\Proyectos\Python\BorisAppBack\app\main\interfaces.py", line 19, in cargar_pedidos
    crear_pedido(dict)
  File "C:\Users\erezzonico\Proyectos\Python\BorisAppBack\app\main\interfaces.py", line 75, in crear_pedido
    flash('Producto {} - monto: {}'.format(unProducto, unProducto.monto_a_devolver))
  File "C:\Users\erezzonico\Proyectos\Python\BorisAppBack\app\models.py", line 128, in __repr__
    return '<Order_Detail {} {} {}>'.format(self.Order_line_number, self.line_number, self.prod_id, self.name)
AttributeError: 'Order_detail' object has no attribute 'Order_line_number'
2021-01-15 15:24:39,903 INFO: Boris startup [in C:\Users\erezzonico\Proyectos\Python\BorisAppBack\app\__init__.py:71]
2021-01-15 15:24:43,161 ERROR: Exception on /cargar_pedidos [GET] [in c:\users\erezzonico\proyectos\python\borisappback\venv\lib\site-packages\flask\app.py:1892]
Traceback (most recent call last):
  File "c:\users\erezzonico\proyectos\python\borisappback\venv\lib\site-packages\flask\app.py", line 2447, in wsgi_app
    response = self.full_dispatch_request()
  File "c:\users\erezzonico\proyectos\python\borisappback\venv\lib\site-packages\flask\app.py", line 1952, in full_dispatch_request
    rv = self.handle_user_exception(e)
  File "c:\users\erezzonico\proyectos\python\borisappback\venv\lib\site-packages\flask\app.py", line 1821, in handle_user_exception
    reraise(exc_type, exc_value, tb)
  File "c:\users\erezzonico\proyectos\python\borisappback\venv\lib\site-packages\flask\_compat.py", line 39, in reraise
    raise value
  File "c:\users\erezzonico\proyectos\python\borisappback\venv\lib\site-packages\flask\app.py", line 1950, in full_dispatch_request
    rv = self.dispatch_request()
  File "c:\users\erezzonico\proyectos\python\borisappback\venv\lib\site-packages\flask\app.py", line 1936, in dispatch_request
    return self.view_functions[rule.endpoint](**req.view_args)
  File "c:\users\erezzonico\proyectos\python\borisappback\venv\lib\site-packages\flask_login\utils.py", line 272, in decorated_view
    return func(*args, **kwargs)
  File "C:\Users\erezzonico\Proyectos\Python\BorisAppBack\app\main\routes.py", line 80, in upload_pedidos
    cargar_pedidos()
  File "C:\Users\erezzonico\Proyectos\Python\BorisAppBack\app\main\interfaces.py", line 19, in cargar_pedidos
    crear_pedido(dict)
  File "C:\Users\erezzonico\Proyectos\Python\BorisAppBack\app\main\interfaces.py", line 75, in crear_pedido
    flash('Producto {} - monto: {}'.format(unProducto, unProducto.monto_a_devolver))
  File "C:\Users\erezzonico\Proyectos\Python\BorisAppBack\app\models.py", line 128, in __repr__
    return '<Order_Detail {} {} {}>'.format(self.Order_line_number, self.line_number, self.prod_id, self.name)
AttributeError: 'Order_detail' object has no attribute 'Order_line_number'
2021-01-15 15:24:59,072 INFO: Boris startup [in C:\Users\erezzonico\Proyectos\Python\BorisAppBack\app\__init__.py:71]
2021-01-15 15:35:43,888 INFO: Boris startup [in C:\Users\erezzonico\Proyectos\Python\BorisAppBack\app\__init__.py:71]
2021-01-15 15:39:06,635 INFO: Boris startup [in C:\Users\erezzonico\Proyectos\Python\BorisAppBack\app\__init__.py:71]
2021-01-15 15:39:48,862 INFO: Boris startup [in C:\Users\erezzonico\Proyectos\Python\BorisAppBack\app\__init__.py:71]
2021-01-15 15:40:45,704 INFO: Boris startup [in C:\Users\erezzonico\Proyectos\Python\BorisAppBack\app\__init__.py:71]
2021-01-15 15:41:20,443 INFO: Boris startup [in C:\Users\erezzonico\Proyectos\Python\BorisAppBack\app\__init__.py:71]
2021-01-15 15:41:46,344 ERROR: Exception on /orden/{ url_for('main.ver_pedidos'} [GET] [in c:\users\erezzonico\proyectos\python\borisappback\venv\lib\site-packages\flask\app.py:1892]
Traceback (most recent call last):
  File "c:\users\erezzonico\proyectos\python\borisappback\venv\lib\site-packages\flask\app.py", line 2447, in wsgi_app
    response = self.full_dispatch_request()
  File "c:\users\erezzonico\proyectos\python\borisappback\venv\lib\site-packages\flask\app.py", line 1952, in full_dispatch_request
    rv = self.handle_user_exception(e)
  File "c:\users\erezzonico\proyectos\python\borisappback\venv\lib\site-packages\flask\app.py", line 1821, in handle_user_exception
    reraise(exc_type, exc_value, tb)
  File "c:\users\erezzonico\proyectos\python\borisappback\venv\lib\site-packages\flask\_compat.py", line 39, in reraise
    raise value
  File "c:\users\erezzonico\proyectos\python\borisappback\venv\lib\site-packages\flask\app.py", line 1950, in full_dispatch_request
    rv = self.dispatch_request()
  File "c:\users\erezzonico\proyectos\python\borisappback\venv\lib\site-packages\flask\app.py", line 1936, in dispatch_request
    return self.view_functions[rule.endpoint](**req.view_args)
  File "c:\users\erezzonico\proyectos\python\borisappback\venv\lib\site-packages\flask_login\utils.py", line 272, in decorated_view
    return func(*args, **kwargs)
  File "C:\Users\erezzonico\Proyectos\Python\BorisAppBack\app\main\routes.py", line 106, in orden
    return render_template('orden.html', orden=orden, orden_linea=orden_linea, customer=orden.buyer)
AttributeError: 'NoneType' object has no attribute 'buyer'
2021-01-15 15:43:05,907 INFO: Boris startup [in C:\Users\erezzonico\Proyectos\Python\BorisAppBack\app\__init__.py:71]
